Workbook

Sheet fixtures
A1: gameweek | B1: season | C1: game_type | D1: round | E1: h_team | F1: a_team | G1: h_manager | H1: a_manager | I1: home_team_id | J1: away_team_id
A2: 1 | B2: 2020/21 | C2: League | D2: Group Stage | E2: MD Twente Twente 1 | F2: Cramond Centurions | G2: =VLOOKUP(E2,Sheet1!$B$1:$D$41,2,FALSE) -> Gordon | H2: =VLOOKUP(F2,Sheet1!$B$1:$D$41,2,FALSE) -> Andy | I2: =VLOOKUP(E2,Sheet1!$B$1:$D$41,3,FALSE) -> 2441126 | J2: =VLOOKUP(F2,Sheet1!$B$1:$D$41,3,FALSE) -> 882240
A3: 1 | B3: 2020/21 | C3: League | D3: Group Stage | E3: HTAFC | F3: Upset Zombies | G3: =VLOOKUP(E3,Sheet1!$B$1:$D$41,2,FALSE) -> Simon | H3: =VLOOKUP(F3,Sheet1!$B$1:$D$41,2,FALSE) -> Keith | I3: =VLOOKUP(E3,Sheet1!$B$1:$D$41,3,FALSE) -> 2438184 | J3: =VLOOKUP(F3,Sheet1!$B$1:$D$41,3,FALSE) -> 2445169
A4: 1 | B4: 2020/21 | C4: League | D4: Group Stage | E4: Mitchell's Magicians | F4: We, The Purple | G4: =VLOOKUP(E4,Sheet1!$B$1:$D$41,2,FALSE) -> Gavin | H4: =VLOOKUP(F4,Sheet1!$B$1:$D$41,2,FALSE) -> James | I4: =VLOOKUP(E4,Sheet1!$B$1:$D$41,3,FALSE) -> 2438353 | J4: =VLOOKUP(F4,Sheet1!$B$1:$D$41,3,FALSE) -> 2439477
A5: 1 | B5: 2020/21 | C5: League | D5: Group Stage | E5: Boly-Wood (and co) | F5: Sammy, You Old Slag | G5: =VLOOKUP(E5,Sheet1!$B$1:$D$41,2,FALSE) -> Walid | H5: =VLOOKUP(F5,Sheet1!$B$1:$D$41,2,FALSE) -> Steven | I5: =VLOOKUP(E5,Sheet1!$B$1:$D$41,3,FALSE) -> 2752114 | J5: =VLOOKUP(F5,Sheet1!$B$1:$D$41,3,FALSE) -> 2440073
A6: =A2+1 -> 2 | B6: 2020/21 | C6: League | D6: Group Stage | E6: Cramond Centurions | F6: Boly-Wood (and co) | G6: =VLOOKUP(E6,Sheet1!$B$1:$D$41,2,FALSE) -> Andy | H6: =VLOOKUP(F6,Sheet1!$B$1:$D$41,2,FALSE) -> Walid | I6: =VLOOKUP(E6,Sheet1!$B$1:$D$41,3,FALSE) -> 882240 | J6: =VLOOKUP(F6,Sheet1!$B$1:$D$41,3,FALSE) -> 2752114
A7: =A3+1 -> 2 | B7: 2020/21 | C7: League | D7: Group Stage | E7: Sammy, You Old Slag | F7: Mitchell's Magicians | G7: =VLOOKUP(E7,Sheet1!$B$1:$D$41,2,FALSE) -> Steven | H7: =VLOOKUP(F7,Sheet1!$B$1:$D$41,2,FALSE) -> Gavin | I7: =VLOOKUP(E7,Sheet1!$B$1:$D$41,3,FALSE) -> 2440073 | J7: =VLOOKUP(F7,Sheet1!$B$1:$D$41,3,FALSE) -> 2438353
A8: =A4+1 -> 2 | B8: 2020/21 | C8: League | D8: Group Stage | E8: We, The Purple | F8: HTAFC | G8: =VLOOKUP(E8,Sheet1!$B$1:$D$41,2,FALSE) -> James | H8: =VLOOKUP(F8,Sheet1!$B$1:$D$41,2,FALSE) -> Simon | I8: =VLOOKUP(E8,Sheet1!$B$1:$D$41,3,FALSE) -> 2439477 | J8: =VLOOKUP(F8,Sheet1!$B$1:$D$41,3,FALSE) -> 2438184
A9: =A5+1 -> 2 | B9: 2020/21 | C9: League | D9: Group Stage | E9: Upset Zombies | F9: MD Twente Twente 1 | G9: =VLOOKUP(E9,Sheet1!$B$1:$D$41,2,FALSE) -> Keith | H9: =VLOOKUP(F9,Sheet1!$B$1:$D$41,2,FALSE) -> Gordon | I9: =VLOOKUP(E9,Sheet1!$B$1:$D$41,3,FALSE) -> 2445169 | J9: =VLOOKUP(F9,Sheet1!$B$1:$D$41,3,FALSE) -> 2441126
A10: =A6+1 -> 3 | B10: 2020/21 | C10: League | D10: Group Stage | E10: Mitchell's Magicians | F10: MD Twente Twente 1 | G10: =VLOOKUP(E10,Sheet1!$B$1:$D$41,2,FALSE) -> Gavin | H10: =VLOOKUP(F10,Sheet1!$B$1:$D$41,2,FALSE) -> Gordon | I10: =VLOOKUP(E10,Sheet1!$B$1:$D$41,3,FALSE) -> 2438353 | J10: =VLOOKUP(F10,Sheet1!$B$1:$D$41,3,FALSE) -> 2441126
A11: =A7+1 -> 3 | B11: 2020/21 | C11: League | D11: Group Stage | E11: Sammy, You Old Slag | F11: We, The Purple | G11: =VLOOKUP(E11,Sheet1!$B$1:$D$41,2,FALSE) -> Steven | H11: =VLOOKUP(F11,Sheet1!$B$1:$D$41,2,FALSE) -> James | I11: =VLOOKUP(E11,Sheet1!$B$1:$D$41,3,FALSE) -> 2440073 | J11: =VLOOKUP(F11,Sheet1!$B$1:$D$41,3,FALSE) -> 2439477
A12: =A8+1 -> 3 | B12: 2020/21 | C12: League | D12: Group Stage | E12: HTAFC | F12: Cramond Centurions | G12: =VLOOKUP(E12,Sheet1!$B$1:$D$41,2,FALSE) -> Simon | H12: =VLOOKUP(F12,Sheet1!$B$1:$D$41,2,FALSE) -> Andy | I12: =VLOOKUP(E12,Sheet1!$B$1:$D$41,3,FALSE) -> 2438184 | J12: =VLOOKUP(F12,Sheet1!$B$1:$D$41,3,FALSE) -> 882240
A13: =A9+1 -> 3 | B13: 2020/21 | C13: League | D13: Group Stage | E13: Boly-Wood (and co) | F13: Upset Zombies | G13: =VLOOKUP(E13,Sheet1!$B$1:$D$41,2,FALSE) -> Walid | H13: =VLOOKUP(F13,Sheet1!$B$1:$D$41,2,FALSE) -> Keith | I13: =VLOOKUP(E13,Sheet1!$B$1:$D$41,3,FALSE) -> 2752114 | J13: =VLOOKUP(F13,Sheet1!$B$1:$D$41,3,FALSE) -> 2445169
A14: =A10+1 -> 4 | B14: 2020/21 | C14: League | D14: Group Stage | E14: Upset Zombies | F14: Mitchell's Magicians | G14: =VLOOKUP(E14,Sheet1!$B$1:$D$41,2,FALSE) -> Keith | H14: =VLOOKUP(F14,Sheet1!$B$1:$D$41,2,FALSE) -> Gavin | I14: =VLOOKUP(E14,Sheet1!$B$1:$D$41,3,FALSE) -> 2445169 | J14: =VLOOKUP(F14,Sheet1!$B$1:$D$41,3,FALSE) -> 2438353
A15: =A11+1 -> 4 | B15: 2020/21 | C15: League | D15: Group Stage | E15: Cramond Centurions | F15: Sammy, You Old Slag | G15: =VLOOKUP(E15,Sheet1!$B$1:$D$41,2,FALSE) -> Andy | H15: =VLOOKUP(F15,Sheet1!$B$1:$D$41,2,FALSE) -> Steven | I15: =VLOOKUP(E15,Sheet1!$B$1:$D$41,3,FALSE) -> 882240 | J15: =VLOOKUP(F15,Sheet1!$B$1:$D$41,3,FALSE) -> 2440073
A16: =A12+1 -> 4 | B16: 2020/21 | C16: League | D16: Group Stage | E16: MD Twente Twente 1 | F16: HTAFC | G16: =VLOOKUP(E16,Sheet1!$B$1:$D$41,2,FALSE) -> Gordon | H16: =VLOOKUP(F16,Sheet1!$B$1:$D$41,2,FALSE) -> Simon | I16: =VLOOKUP(E16,Sheet1!$B$1:$D$41,3,FALSE) -> 2441126 | J16: =VLOOKUP(F16,Sheet1!$B$1:$D$41,3,FALSE) -> 2438184
A17: =A13+1 -> 4 | B17: 2020/21 | C17: League | D17: Group Stage | E17: Boly-Wood (and co) | F17: We, The Purple | G17: =VLOOKUP(E17,Sheet1!$B$1:$D$41,2,FALSE) -> Walid | H17: =VLOOKUP(F17,Sheet1!$B$1:$D$41,2,FALSE) -> James | I17: =VLOOKUP(E17,Sheet1!$B$1:$D$41,3,FALSE) -> 2752114 | J17: =VLOOKUP(F17,Sheet1!$B$1:$D$41,3,FALSE) -> 2439477
... A81: =A77+1 -> 20 | B81: 2020/21 | C81: League | D81: Group Stage | E81: Boly-Wood (and co) | F81: MD Twente Twente 1 | G81: =VLOOKUP(E81,Sheet1!$B$1:$D$41,2,FALSE) -> Walid | H81: =VLOOKUP(F81,Sheet1!$B$1:$D$41,2,FALSE) -> Gordon | I81: =VLOOKUP(E81,Sheet1!$B$1:$D$41,3,FALSE) -> 2752114 | J81: =VLOOKUP(F81,Sheet1!$B$1:$D$41,3,FALSE) -> 2441126
A82: 21 | B82: 2020/21 | C82: Cup | D82: Quarter Final | E82: Cramond Centurions | F82: Sammy, You Old Slag | G82: =VLOOKUP(E82,Sheet1!$B$1:$D$41,2,FALSE) -> Andy | H82: =VLOOKUP(F82,Sheet1!$B$1:$D$41,2,FALSE) -> Steven | I82: =VLOOKUP(E82,Sheet1!$B$1:$D$41,3,FALSE) -> 882240 | J82: =VLOOKUP(F82,Sheet1!$B$1:$D$41,3,FALSE) -> 2440073
A83: 21 | B83: 2020/21 | C83: Cup | D83: Quarter Final | E83: Upset Zombies | F83: Mitchell's Magicians | G83: =VLOOKUP(E83,Sheet1!$B$1:$D$41,2,FALSE) -> Keith | H83: =VLOOKUP(F83,Sheet1!$B$1:$D$41,2,FALSE) -> Gavin | I83: =VLOOKUP(E83,Sheet1!$B$1:$D$41,3,FALSE) -> 2445169 | J83: =VLOOKUP(F83,Sheet1!$B$1:$D$41,3,FALSE) -> 2438353
A84: 21 | B84: 2020/21 | C84: Cup | D84: Quarter Final | E84: Mitchell's Magicians | F84: Upset Zombies | G84: =VLOOKUP(E84,Sheet1!$B$1:$D$41,2,FALSE) -> Gavin | H84: =VLOOKUP(F84,Sheet1!$B$1:$D$41,2,FALSE) -> Keith | I84: =VLOOKUP(E84,Sheet1!$B$1:$D$41,3,FALSE) -> 2438353 | J84: =VLOOKUP(F84,Sheet1!$B$1:$D$41,3,FALSE) -> 2445169
A85: 21 | B85: 2020/21 | C85: Cup | D85: Quarter Final | E85: Sammy, You Old Slag | F85: Cramond Centurions | G85: =VLOOKUP(E85,Sheet1!$B$1:$D$41,2,FALSE) -> Steven | H85: =VLOOKUP(F85,Sheet1!$B$1:$D$41,2,FALSE) -> Andy | I85: =VLOOKUP(E85,Sheet1!$B$1:$D$41,3,FALSE) -> 2440073 | J85: =VLOOKUP(F85,Sheet1!$B$1:$D$41,3,FALSE) -> 882240
A86: =A82+1 -> 22 | B86: 2020/21 | C86: League | D86: Group Stage | E86: Mitchell's Magicians | F86: Boly-Wood (and co) | G86: =VLOOKUP(E86,Sheet1!$B$1:$D$41,2,FALSE) -> Gavin | H86: =VLOOKUP(F86,Sheet1!$B$1:$D$41,2,FALSE) -> Walid | I86: =VLOOKUP(E86,Sheet1!$B$1:$D$41,3,FALSE) -> 2438353 | J86: =VLOOKUP(F86,Sheet1!$B$1:$D$41,3,FALSE) -> 2752114
A87: =A83+1 -> 22 | B87: 2020/21 | C87: League | D87: Group Stage | E87: MD Twente Twente 1 | F87: We, The Purple | G87: =VLOOKUP(E87,Sheet1!$B$1:$D$41,2,FALSE) -> Gordon | H87: =VLOOKUP(F87,Sheet1!$B$1:$D$41,2,FALSE) -> James | I87: =VLOOKUP(E87,Sheet1!$B$1:$D$41,3,FALSE) -> 2441126 | J87: =VLOOKUP(F87,Sheet1!$B$1:$D$41,3,FALSE) -> 2439477
A88: =A84+1 -> 22 | B88: 2020/21 | C88: League | D88: Group Stage | E88: HTAFC | F88: Sammy, You Old Slag | G88: =VLOOKUP(E88,Sheet1!$B$1:$D$41,2,FALSE) -> Simon | H88: =VLOOKUP(F88,Sheet1!$B$1:$D$41,2,FALSE) -> Steven | I88: =VLOOKUP(E88,Sheet1!$B$1:$D$41,3,FALSE) -> 2438184 | J88: =VLOOKUP(F88,Sheet1!$B$1:$D$41,3,FALSE) -> 2440073
A89: =A85+1 -> 22 | B89: 2020/21 | C89: League | D89: Group Stage | E89: Upset Zombies | F89: Cramond Centurions | G89: =VLOOKUP(E89,Sheet1!$B$1:$D$41,2,FALSE) -> Keith | H89: =VLOOKUP(F89,Sheet1!$B$1:$D$41,2,FALSE) -> Andy | I89: =VLOOKUP(E89,Sheet1!$B$1:$D$41,3,FALSE) -> 2445169 | J89: =VLOOKUP(F89,Sheet1!$B$1:$D$41,3,FALSE) -> 882240
A90: 22 | B90: 2020/21 | C90: Cup | D90: Quarter Final | E90: Boly-Wood (and co) | F90: HTAFC | G90: =VLOOKUP(E90,Sheet1!$B$1:$D$41,2,FALSE) -> Walid | H90: =VLOOKUP(F90,Sheet1!$B$1:$D$41,2,FALSE) -> Simon | I90: =VLOOKUP(E90,Sheet1!$B$1:$D$41,3,FALSE) -> 2752114 | J90: =VLOOKUP(F90,Sheet1!$B$1:$D$41,3,FALSE) -> 2438184
A91: 22 | B91: 2020/21 | C91: Cup | D91: Quarter Final | E91: HTAFC | F91: Boly-Wood (and co) | G91: =VLOOKUP(E91,Sheet1!$B$1:$D$41,2,FALSE) -> Simon | H91: =VLOOKUP(F91,Sheet1!$B$1:$D$41,2,FALSE) -> Walid | I91: =VLOOKUP(E91,Sheet1!$B$1:$D$41,3,FALSE) -> 2438184 | J91: =VLOOKUP(F91,Sheet1!$B$1:$D$41,3,FALSE) -> 2752114
A92: 22 | B92: 2020/21 | C92: Cup | D92: Quarter Final | E92: MD Twente Twente 1 | F92: We, The Purple | G92: =VLOOKUP(E92,Sheet1!$B$1:$D$41,2,FALSE) -> Gordon | H92: =VLOOKUP(F92,Sheet1!$B$1:$D$41,2,FALSE) -> James | I92: =VLOOKUP(E92,Sheet1!$B$1:$D$41,3,FALSE) -> 2441126 | J92: =VLOOKUP(F92,Sheet1!$B$1:$D$41,3,FALSE) -> 2439477
A93: 22 | B93: 2020/21 | C93: Cup | D93: Quarter Final | E93: We, The Purple | F93: MD Twente Twente 1 | G93: =VLOOKUP(E93,Sheet1!$B$1:$D$41,2,FALSE) -> James | H93: =VLOOKUP(F93,Sheet1!$B$1:$D$41,2,FALSE) -> Gordon | I93: =VLOOKUP(E93,Sheet1!$B$1:$D$41,3,FALSE) -> 2439477 | J93: =VLOOKUP(F93,Sheet1!$B$1:$D$41,3,FALSE) -> 2441126
A94: =A90+1 -> 23 | B94: 2020/21 | C94: League | D94: Group Stage | E94: MD Twente Twente 1 | F94: Cramond Centurions | G94: =VLOOKUP(E94,Sheet1!$B$1:$D$41,2,FALSE) -> Gordon | H94: =VLOOKUP(F94,Sheet1!$B$1:$D$41,2,FALSE) -> Andy | I94: =VLOOKUP(E94,Sheet1!$B$1:$D$41,3,FALSE) -> 2441126 | J94: =VLOOKUP(F94,Sheet1!$B$1:$D$41,3,FALSE) -> 882240
A95: =A91+1 -> 23 | B95: 2020/21 | C95: League | D95: Group Stage | E95: HTAFC | F95: Upset Zombies | G95: =VLOOKUP(E95,Sheet1!$B$1:$D$41,2,FALSE) -> Simon | H95: =VLOOKUP(F95,Sheet1!$B$1:$D$41,2,FALSE) -> Keith | I95: =VLOOKUP(E95,Sheet1!$B$1:$D$41,3,FALSE) -> 2438184 | J95: =VLOOKUP(F95,Sheet1!$B$1:$D$41,3,FALSE) -> 2445169
A96: =A92+1 -> 23 | B96: 2020/21 | C96: League | D96: Group Stage | E96: Mitchell's Magicians | F96: We, The Purple | G96: =VLOOKUP(E96,Sheet1!$B$1:$D$41,2,FALSE) -> Gavin | H96: =VLOOKUP(F96,Sheet1!$B$1:$D$41,2,FALSE) -> James | I96: =VLOOKUP(E96,Sheet1!$B$1:$D$41,3,FALSE) -> 2438353 | J96: =VLOOKUP(F96,Sheet1!$B$1:$D$41,3,FALSE) -> 2439477
A97: =A93+1 -> 23 | B97: 2020/21 | C97: League | D97: Group Stage | E97: Boly-Wood (and co) | F97: Sammy, You Old Slag | G97: =VLOOKUP(E97,Sheet1!$B$1:$D$41,2,FALSE) -> Walid | H97: =VLOOKUP(F97,Sheet1!$B$1:$D$41,2,FALSE) -> Steven | I97: =VLOOKUP(E97,Sheet1!$B$1:$D$41,3,FALSE) -> 2752114 | J97: =VLOOKUP(F97,Sheet1!$B$1:$D$41,3,FALSE) -> 2440073
A98: 23 | B98: 2020/21 | C98: Cup | D98: Semi Final | E98: Upset Zombies | F98: Sammy, You Old Slag | G98: =VLOOKUP(E98,Sheet1!$B$1:$D$41,2,FALSE) -> Keith | H98: =VLOOKUP(F98,Sheet1!$B$1:$D$41,2,FALSE) -> Steven | I98: =VLOOKUP(E98,Sheet1!$B$1:$D$41,3,FALSE) -> 2445169 | J98: =VLOOKUP(F98,Sheet1!$B$1:$D$41,3,FALSE) -> 2440073
A99: 23 | B99: 2020/21 | C99: Cup | D99: Semi Final | E99: Sammy, You Old Slag | F99: Upset Zombies | G99: =VLOOKUP(E99,Sheet1!$B$1:$D$41,2,FALSE) -> Steven | H99: =VLOOKUP(F99,Sheet1!$B$1:$D$41,2,FALSE) -> Keith | I99: =VLOOKUP(E99,Sheet1!$B$1:$D$41,3,FALSE) -> 2440073 | J99: =VLOOKUP(F99,Sheet1!$B$1:$D$41,3,FALSE) -> 2445169
A100: =A96+1 -> 24 | B100: 2020/21 | C100: League | D100: Group Stage | E100: Cramond Centurions | F100: Boly-Wood (and co) | G100: =VLOOKUP(E100,Sheet1!$B$1:$D$41,2,FALSE) -> Andy | H100: =VLOOKUP(F100,Sheet1!$B$1:$D$41,2,FALSE) -> Walid | I100: =VLOOKUP(E100,Sheet1!$B$1:$D$41,3,FALSE) -> 882240 | J100: =VLOOKUP(F100,Sheet1!$B$1:$D$41,3,FALSE) -> 2752114
A101: =A97+1 -> 24 | B101: 2020/21 | C101: League | D101: Group Stage | E101: Sammy, You Old Slag | F101: Mitchell's Magicians | G101: =VLOOKUP(E101,Sheet1!$B$1:$D$41,2,FALSE) -> Steven | H101: =VLOOKUP(F101,Sheet1!$B$1:$D$41,2,FALSE) -> Gavin | I101: =VLOOKUP(E101,Sheet1!$B$1:$D$41,3,FALSE) -> 2440073 | J101: =VLOOKUP(F101,Sheet1!$B$1:$D$41,3,FALSE) -> 2438353
A102: =A98+1 -> 24 | B102: 2020/21 | C102: League | D102: Group Stage | E102: We, The Purple | F102: HTAFC | G102: =VLOOKUP(E102,Sheet1!$B$1:$D$41,2,FALSE) -> James | H102: =VLOOKUP(F102,Sheet1!$B$1:$D$41,2,FALSE) -> Simon | I102: =VLOOKUP(E102,Sheet1!$B$1:$D$41,3,FALSE) -> 2439477 | J102: =VLOOKUP(F102,Sheet1!$B$1:$D$41,3,FALSE) -> 2438184
A103: =A99+1 -> 24 | B103: 2020/21 | C103: League | D103: Group Stage | E103: Upset Zombies | F103: MD Twente Twente 1 | G103: =VLOOKUP(E103,Sheet1!$B$1:$D$41,2,FALSE) -> Keith | H103: =VLOOKUP(F103,Sheet1!$B$1:$D$41,2,FALSE) -> Gordon | I103: =VLOOKUP(E103,Sheet1!$B$1:$D$41,3,FALSE) -> 2445169 | J103: =VLOOKUP(F103,Sheet1!$B$1:$D$41,3,FALSE) -> 2441126
...

Sheet Sheet1
A1: season | B1: team | C1: name | D1: id
A2: Season 2020/21 | B2: Cramond Centurions | C2: Andy | D2: 882240
A3: Season 2020/21 | B3: Mitchell's Magicians | C3: Gavin | D3: 2438353
A4: Season 2020/21 | B4: MD Twente Twente 1 | C4: Gordon | D4: 2441126
A5: Season 2020/21 | B5: We, The Purple | C5: James | D5: 2439477
A6: Season 2020/21 | B6: Upset Zombies | C6: Keith | D6: 2445169
A7: Season 2020/21 | B7: HTAFC | C7: Simon | D7: 2438184
A8: Season 2020/21 | B8: Sammy, You Old Slag | C8: Steven | D8: 2440073
A9: Season 2020/21 | B9: Boly-Wood (and co) | C9: Walid | D9: 2752114
A10: Season 2021/22 | B10: Sink the Bismarck! | C10: Andy | D10: 36150
A11: Season 2021/22 | B11: Mitchell's Macho Men | C11: Gavin | D11: 3801379
A12: Season 2021/22 | B12: Gordys Gophers | C12: Gordon | D12: 2347381
A13: Season 2021/22 | B13: Sweaty Raphael | C13: James | D13: 16280
... A33: Season 2023/24 | B33: It's Haal Over | C33: Walid | D33: 2955408
A34: Season 2024/25 | C34: Andy | D34: 96097
A35: Season 2024/25 | C35: Gavin | D35: 6186573
A36: Season 2024/25 | C36: Gordon | D36: 10946
A37: Season 2024/25 | C37: James | D37: 109884
A38: Season 2024/25 | C38: Keith | D38: 6188948
A39: Season 2024/25 | C39: Simon | D39: 1114016
A40: Season 2024/25 | C40: Steven | D40: 1077612
A41: Season 2024/25 | C41: Walid | D41: 1123161
